============================= test session starts ==============================
platform linux -- Python 3.9.2, pytest-6.2.2, py-1.10.0, pluggy-0.13.1
rootdir: /home/stidsem4/iut/2021/controle/yael.schoulal/c16_03
collected 7 items

test_16_03.py F....FF                                                    [100%]

=================================== FAILURES ===================================
_____________________________ Test1603sute.test_10 _____________________________

self = <c16_03.test_16_03.Test1603sute testMethod=test_10>

    def test_10(self):
        try:
            from .main  import Note
        except:
           assert False
        try:
>           Note.vider()
E           AttributeError: type object 'Note' has no attribute 'vider'

test_16_03.py:98: AttributeError

During handling of the above exception, another exception occurred:

self = <c16_03.test_16_03.Test1603sute testMethod=test_10>

    def test_10(self):
        try:
            from .main  import Note
        except:
           assert False
        try:
            Note.vider()
        except:
>           assert False
E           AssertionError: assert False

test_16_03.py:100: AssertionError
----------------------------- Captured stdout call -----------------------------
[('eleve1', 'math', 13), ('eleve1', 'physique', 15), ('eleve1', 'math', 13), ('eleve1', 'eco', 12), ('eleve1', 'eco', 13), ('eleve1', 'math', 12), ('eleve2', 'math', 13), ('eleve2', 'math', 14)]
[13, 15, 13, 12, 13, 12, 13, 14]
13.125
['eleve1', 'eleve1', 'eleve1', 'eleve1', 'eleve1', 'eleve1', 'eleve2', 'eleve2']
['math', 'physique', 'math', 'eco', 'eco', 'math', 'math', 'math']
eleve2
maths
13
eleve eleve2 matiere maths note 13
eleve2
maths
14
eleve eleve2 matiere maths note 14
eleve1
physique
15
eleve eleve1 matiere physique note 15
eleve1
eco
12
eleve eleve1 matiere eco note 12
eleve1
eco
13
eleve eleve1 matiere eco note 13
eleve1
maths
13
eleve eleve1 matiere maths note 13
eleve1
maths
13
eleve eleve1 matiere maths note 13
eleve1
maths
12
eleve eleve1 matiere maths note 12
12.666666666666666
12.5
13.5
15.0
[13, 15, 13, 12, 13, 12, 13, 14]
_____________________________ Test1603sute.test_8 ______________________________

self = <c16_03.test_16_03.Test1603sute testMethod=test_8>

    def test_8(self):
        try:
            from .main import Note
        except ImportError:
            assert False, "import de Note impossible"
        try:
>           from .main  import moyenne_Notes as mnotes
E           ImportError: cannot import name 'moyenne_Notes' from 'c16_03.main' (/home/stidsem4/iut/2021/controle/yael.schoulal/c16_03/main.py)

test_16_03.py:71: ImportError

During handling of the above exception, another exception occurred:

self = <c16_03.test_16_03.Test1603sute testMethod=test_8>

    def test_8(self):
        try:
            from .main import Note
        except ImportError:
            assert False, "import de Note impossible"
        try:
            from .main  import moyenne_Notes as mnotes
        except ImportError:
            try:
>               from .main  import moyenne_notes as mnotes
E               ImportError: cannot import name 'moyenne_notes' from 'c16_03.main' (/home/stidsem4/iut/2021/controle/yael.schoulal/c16_03/main.py)

test_16_03.py:74: ImportError

During handling of the above exception, another exception occurred:

self = <c16_03.test_16_03.Test1603sute testMethod=test_8>

    def test_8(self):
        try:
            from .main import Note
        except ImportError:
            assert False, "import de Note impossible"
        try:
            from .main  import moyenne_Notes as mnotes
        except ImportError:
            try:
                from .main  import moyenne_notes as mnotes
            except ImportError:
>               assert False, "La fonction moyenne_notes n'est pas définie"
E               AssertionError: La fonction moyenne_notes n'est pas définie
E               assert False

test_16_03.py:76: AssertionError
_____________________________ Test1603sute.test_9 ______________________________

self = <c16_03.test_16_03.Test1603sute testMethod=test_9>

    def test_9(self):
        try:
            from .main  import Note
        except:
           assert False
>       assert hasattr(Note, 'instances')
E       AssertionError: assert False
E        +  where False = hasattr(<class 'c16_03.main.Note'>, 'instances')

test_16_03.py:90: AssertionError
=========================== short test summary info ============================
FAILED test_16_03.py::Test1603sute::test_10 - AssertionError: assert False
FAILED test_16_03.py::Test1603sute::test_8 - AssertionError: La fonction moye...
FAILED test_16_03.py::Test1603sute::test_9 - AssertionError: assert False
========================= 3 failed, 4 passed in 0.06s ==========================
